2023-02-02 13:38:48,818 INFO    StreamThr :2610 [internal.py:wandb_internal():90] W&B internal server running at pid: 2610, started at: 2023-02-02 13:38:48.817903
2023-02-02 13:38:48,819 DEBUG   HandlerThread:2610 [handler.py:handle_request():144] handle_request: status
2023-02-02 13:38:48,823 INFO    WriterThread:2610 [datastore.py:open_for_write():85] open: /home/filippo/Desktop/Project/Experiments/JacoRLDR/sac/wandb/run-20230202_133848-rr5hsgq6/run-rr5hsgq6.wandb
2023-02-02 13:38:48,823 DEBUG   SenderThread:2610 [sender.py:send():334] send: header
2023-02-02 13:38:48,838 DEBUG   SenderThread:2610 [sender.py:send():334] send: run
2023-02-02 13:38:52,366 INFO    SenderThread:2610 [retry.py:__call__():169] Retry attempt failed:
Traceback (most recent call last):
  File "/home/filippo/miniconda3/envs/robot/lib/python3.7/site-packages/urllib3/connection.py", line 175, in _new_conn
    (self._dns_host, self.port), self.timeout, **extra_kw
  File "/home/filippo/miniconda3/envs/robot/lib/python3.7/site-packages/urllib3/util/connection.py", line 72, in create_connection
    for res in socket.getaddrinfo(host, port, family, socket.SOCK_STREAM):
  File "/home/filippo/miniconda3/envs/robot/lib/python3.7/socket.py", line 752, in getaddrinfo
    for res in _socket.getaddrinfo(host, port, family, type, proto, flags):
socket.gaierror: [Errno -3] Temporary failure in name resolution

During handling of the above exception, another exception occurred:

Traceback (most recent call last):
  File "/home/filippo/miniconda3/envs/robot/lib/python3.7/site-packages/urllib3/connectionpool.py", line 710, in urlopen
    chunked=chunked,
  File "/home/filippo/miniconda3/envs/robot/lib/python3.7/site-packages/urllib3/connectionpool.py", line 386, in _make_request
    self._validate_conn(conn)
  File "/home/filippo/miniconda3/envs/robot/lib/python3.7/site-packages/urllib3/connectionpool.py", line 1042, in _validate_conn
    conn.connect()
  File "/home/filippo/miniconda3/envs/robot/lib/python3.7/site-packages/urllib3/connection.py", line 358, in connect
    self.sock = conn = self._new_conn()
  File "/home/filippo/miniconda3/envs/robot/lib/python3.7/site-packages/urllib3/connection.py", line 187, in _new_conn
    self, "Failed to establish a new connection: %s" % e
urllib3.exceptions.NewConnectionError: <urllib3.connection.HTTPSConnection object at 0x7feb1c511350>: Failed to establish a new connection: [Errno -3] Temporary failure in name resolution

During handling of the above exception, another exception occurred:

Traceback (most recent call last):
  File "/home/filippo/miniconda3/envs/robot/lib/python3.7/site-packages/requests/adapters.py", line 499, in send
    timeout=timeout,
  File "/home/filippo/miniconda3/envs/robot/lib/python3.7/site-packages/urllib3/connectionpool.py", line 788, in urlopen
    method, url, error=e, _pool=self, _stacktrace=sys.exc_info()[2]
  File "/home/filippo/miniconda3/envs/robot/lib/python3.7/site-packages/urllib3/util/retry.py", line 592, in increment
    raise MaxRetryError(_pool, url, error or ResponseError(cause))
urllib3.exceptions.MaxRetryError: HTTPSConnectionPool(host='api.wandb.ai', port=443): Max retries exceeded with url: /graphql (Caused by NewConnectionError('<urllib3.connection.HTTPSConnection object at 0x7feb1c511350>: Failed to establish a new connection: [Errno -3] Temporary failure in name resolution'))

During handling of the above exception, another exception occurred:

Traceback (most recent call last):
  File "/home/filippo/miniconda3/envs/robot/lib/python3.7/site-packages/wandb/sdk/lib/retry.py", line 128, in __call__
    result = self._call_fn(*args, **kwargs)
  File "/home/filippo/miniconda3/envs/robot/lib/python3.7/site-packages/wandb/sdk/internal/internal_api.py", line 241, in execute
    return self.client.execute(*args, **kwargs)  # type: ignore
  File "/home/filippo/miniconda3/envs/robot/lib/python3.7/site-packages/wandb/vendor/gql-0.2.0/wandb_gql/client.py", line 52, in execute
    result = self._get_result(document, *args, **kwargs)
  File "/home/filippo/miniconda3/envs/robot/lib/python3.7/site-packages/wandb/vendor/gql-0.2.0/wandb_gql/client.py", line 60, in _get_result
    return self.transport.execute(document, *args, **kwargs)
  File "/home/filippo/miniconda3/envs/robot/lib/python3.7/site-packages/wandb/vendor/gql-0.2.0/wandb_gql/transport/requests.py", line 38, in execute
    request = requests.post(self.url, **post_args)
  File "/home/filippo/miniconda3/envs/robot/lib/python3.7/site-packages/requests/api.py", line 115, in post
    return request("post", url, data=data, json=json, **kwargs)
  File "/home/filippo/miniconda3/envs/robot/lib/python3.7/site-packages/requests/api.py", line 59, in request
    return session.request(method=method, url=url, **kwargs)
  File "/home/filippo/miniconda3/envs/robot/lib/python3.7/site-packages/requests/sessions.py", line 587, in request
    resp = self.send(prep, **send_kwargs)
  File "/home/filippo/miniconda3/envs/robot/lib/python3.7/site-packages/requests/sessions.py", line 701, in send
    r = adapter.send(request, **kwargs)
  File "/home/filippo/miniconda3/envs/robot/lib/python3.7/site-packages/requests/adapters.py", line 565, in send
    raise ConnectionError(e, request=request)
requests.exceptions.ConnectionError: HTTPSConnectionPool(host='api.wandb.ai', port=443): Max retries exceeded with url: /graphql (Caused by NewConnectionError('<urllib3.connection.HTTPSConnection object at 0x7feb1c511350>: Failed to establish a new connection: [Errno -3] Temporary failure in name resolution'))
2023-02-02 13:38:53,841 DEBUG   HandlerThread:2610 [handler.py:handle_request():144] handle_request: keepalive
2023-02-02 13:38:58,842 DEBUG   HandlerThread:2610 [handler.py:handle_request():144] handle_request: keepalive
2023-02-02 13:39:03,844 DEBUG   HandlerThread:2610 [handler.py:handle_request():144] handle_request: keepalive
2023-02-02 13:39:08,846 DEBUG   HandlerThread:2610 [handler.py:handle_request():144] handle_request: keepalive
2023-02-02 13:39:13,848 DEBUG   HandlerThread:2610 [handler.py:handle_request():144] handle_request: keepalive
2023-02-02 13:40:59,441 INFO    SenderThread:2610 [dir_watcher.py:__init__():216] watching files in: /home/filippo/Desktop/Project/Experiments/JacoRLDR/sac/wandb/run-20230202_133848-rr5hsgq6/files
2023-02-02 13:40:59,441 INFO    SenderThread:2610 [sender.py:_start_run_threads():1068] run started: rr5hsgq6 with start time 1675312728.818158
2023-02-02 13:40:59,441 DEBUG   HandlerThread:2610 [handler.py:handle_request():144] handle_request: status_report
2023-02-02 13:41:04,442 DEBUG   HandlerThread:2610 [handler.py:handle_request():144] handle_request: status_report
2023-02-02 13:41:09,442 DEBUG   HandlerThread:2610 [handler.py:handle_request():144] handle_request: status_report
2023-02-02 13:41:15,218 DEBUG   HandlerThread:2610 [handler.py:handle_request():144] handle_request: status_report
2023-02-02 13:41:20,219 DEBUG   HandlerThread:2610 [handler.py:handle_request():144] handle_request: status_report
2023-02-02 13:41:25,221 DEBUG   HandlerThread:2610 [handler.py:handle_request():144] handle_request: status_report
2023-02-02 13:41:30,222 DEBUG   HandlerThread:2610 [handler.py:handle_request():144] handle_request: status_report
2023-02-02 13:41:35,223 DEBUG   HandlerThread:2610 [handler.py:handle_request():144] handle_request: status_report
2023-02-02 13:41:40,224 DEBUG   HandlerThread:2610 [handler.py:handle_request():144] handle_request: status_report
2023-02-02 13:41:45,226 DEBUG   HandlerThread:2610 [handler.py:handle_request():144] handle_request: status_report
2023-02-02 13:41:50,227 DEBUG   HandlerThread:2610 [handler.py:handle_request():144] handle_request: status_report
2023-02-02 13:41:55,228 DEBUG   HandlerThread:2610 [handler.py:handle_request():144] handle_request: status_report
2023-02-02 13:42:00,229 DEBUG   HandlerThread:2610 [handler.py:handle_request():144] handle_request: status_report
2023-02-02 13:42:05,229 DEBUG   HandlerThread:2610 [handler.py:handle_request():144] handle_request: status_report
2023-02-02 13:42:10,231 DEBUG   HandlerThread:2610 [handler.py:handle_request():144] handle_request: status_report
2023-02-02 13:42:15,233 DEBUG   HandlerThread:2610 [handler.py:handle_request():144] handle_request: status_report
2023-02-02 13:42:20,234 DEBUG   HandlerThread:2610 [handler.py:handle_request():144] handle_request: status_report
2023-02-02 13:42:25,237 DEBUG   HandlerThread:2610 [handler.py:handle_request():144] handle_request: status_report
2023-02-02 13:42:30,239 DEBUG   HandlerThread:2610 [handler.py:handle_request():144] handle_request: status_report
2023-02-02 13:42:35,240 DEBUG   HandlerThread:2610 [handler.py:handle_request():144] handle_request: status_report
2023-02-02 13:42:40,242 DEBUG   HandlerThread:2610 [handler.py:handle_request():144] handle_request: status_report
2023-02-02 13:42:45,243 DEBUG   HandlerThread:2610 [handler.py:handle_request():144] handle_request: status_report
2023-02-02 13:42:50,245 DEBUG   HandlerThread:2610 [handler.py:handle_request():144] handle_request: status_report
2023-02-02 13:42:55,246 DEBUG   HandlerThread:2610 [handler.py:handle_request():144] handle_request: status_report
2023-02-02 13:43:00,247 DEBUG   HandlerThread:2610 [handler.py:handle_request():144] handle_request: status_report
2023-02-02 13:43:05,249 DEBUG   HandlerThread:2610 [handler.py:handle_request():144] handle_request: status_report
2023-02-02 13:43:10,250 DEBUG   HandlerThread:2610 [handler.py:handle_request():144] handle_request: status_report
2023-02-02 13:43:15,251 DEBUG   HandlerThread:2610 [handler.py:handle_request():144] handle_request: status_report
2023-02-02 13:43:20,253 DEBUG   HandlerThread:2610 [handler.py:handle_request():144] handle_request: status_report
2023-02-02 13:43:25,255 DEBUG   HandlerThread:2610 [handler.py:handle_request():144] handle_request: status_report
2023-02-02 13:43:30,256 DEBUG   HandlerThread:2610 [handler.py:handle_request():144] handle_request: status_report
2023-02-02 13:43:35,257 DEBUG   HandlerThread:2610 [handler.py:handle_request():144] handle_request: status_report
2023-02-02 13:43:40,258 DEBUG   HandlerThread:2610 [handler.py:handle_request():144] handle_request: status_report
2023-02-02 13:43:45,260 DEBUG   HandlerThread:2610 [handler.py:handle_request():144] handle_request: status_report
2023-02-02 13:43:50,261 DEBUG   HandlerThread:2610 [handler.py:handle_request():144] handle_request: status_report
2023-02-02 13:43:51,701 INFO    MainThread:2610 [internal.py:handle_exit():77] Internal process exited
